2017-04-17 13:12:51,534 [ERROR]  --------------------------------------------------------------------------------
2017-04-17 13:12:51,534 [ERROR]  Traceback (most recent call last):
  File "message_handler.py", line 169, in voices_handler
    text_handler(message)
  File "message_handler.py", line 214, in text_handler
    parser = query_parser(message.text)
  File "message_handler.py", line 99, in query_parser
    radius_query = int(radius[0]) if int(radius[0]) <= 50000 else radius_query
ValueError: invalid literal for int() with base 10: ''

2017-04-17 13:12:51,549 [ERROR]  --------------------------------------------------------------------------------
2017-04-17 13:12:51,549 [ERROR]  --------------------------------------------------------------------------------
2017-04-17 13:12:51,549 [ERROR]  invalid literal for int() with base 10: ''
2017-04-17 13:12:51,549 [ERROR]  --------------------------------------------------------------------------------
2017-04-17 13:14:28,781 [ERROR]  Exception during reset or similar
Traceback (most recent call last):
  File "E:\Work\Programs\Python3.6.0\lib\site-packages\werkzeug\serving.py", line 74, in <module>
    import SocketServer as socketserver
ModuleNotFoundError: No module named 'SocketServer'

During handling of the above exception, another exception occurred:

Traceback (most recent call last):
  File "E:\Work\Programs\Python3.6.0\lib\site-packages\sqlalchemy\pool.py", line 687, in _finalize_fairy
    fairy._reset(pool)
  File "E:\Work\Programs\Python3.6.0\lib\site-packages\sqlalchemy\pool.py", line 829, in _reset
    pool._dialect.do_rollback(self)
  File "E:\Work\Programs\Python3.6.0\lib\site-packages\sqlalchemy\engine\default.py", line 440, in do_rollback
    dbapi_connection.rollback()
sqlite3.ProgrammingError: SQLite objects created in a thread can only be used in that same thread.The object was created in thread id 11036 and this is thread id 8228
2017-04-17 13:14:28,781 [ERROR]  Exception closing connection <sqlite3.Connection object at 0x04B6C720>
Traceback (most recent call last):
  File "E:\Work\Programs\Python3.6.0\lib\site-packages\werkzeug\serving.py", line 74, in <module>
    import SocketServer as socketserver
ModuleNotFoundError: No module named 'SocketServer'

During handling of the above exception, another exception occurred:

Traceback (most recent call last):
  File "E:\Work\Programs\Python3.6.0\lib\site-packages\sqlalchemy\pool.py", line 687, in _finalize_fairy
    fairy._reset(pool)
  File "E:\Work\Programs\Python3.6.0\lib\site-packages\sqlalchemy\pool.py", line 829, in _reset
    pool._dialect.do_rollback(self)
  File "E:\Work\Programs\Python3.6.0\lib\site-packages\sqlalchemy\engine\default.py", line 440, in do_rollback
    dbapi_connection.rollback()
sqlite3.ProgrammingError: SQLite objects created in a thread can only be used in that same thread.The object was created in thread id 11036 and this is thread id 8228

During handling of the above exception, another exception occurred:

Traceback (most recent call last):
  File "E:\Work\Programs\Python3.6.0\lib\site-packages\sqlalchemy\pool.py", line 300, in _close_connection
    self._dialect.do_close(connection)
  File "E:\Work\Programs\Python3.6.0\lib\site-packages\sqlalchemy\engine\default.py", line 446, in do_close
    dbapi_connection.close()
sqlite3.ProgrammingError: SQLite objects created in a thread can only be used in that same thread.The object was created in thread id 11036 and this is thread id 8228
2017-04-17 13:14:28,859 [ERROR]  Exception during reset or similar
Traceback (most recent call last):
  File "E:\Work\Programs\Python3.6.0\lib\site-packages\sqlalchemy\pool.py", line 687, in _finalize_fairy
    fairy._reset(pool)
  File "E:\Work\Programs\Python3.6.0\lib\site-packages\sqlalchemy\pool.py", line 829, in _reset
    pool._dialect.do_rollback(self)
  File "E:\Work\Programs\Python3.6.0\lib\site-packages\sqlalchemy\engine\default.py", line 440, in do_rollback
    dbapi_connection.rollback()
sqlite3.ProgrammingError: SQLite objects created in a thread can only be used in that same thread.The object was created in thread id 1676 and this is thread id 8228
2017-04-17 13:14:28,859 [ERROR]  Exception closing connection <sqlite3.Connection object at 0x04B6C620>
Traceback (most recent call last):
  File "E:\Work\Programs\Python3.6.0\lib\site-packages\sqlalchemy\pool.py", line 687, in _finalize_fairy
    fairy._reset(pool)
  File "E:\Work\Programs\Python3.6.0\lib\site-packages\sqlalchemy\pool.py", line 829, in _reset
    pool._dialect.do_rollback(self)
  File "E:\Work\Programs\Python3.6.0\lib\site-packages\sqlalchemy\engine\default.py", line 440, in do_rollback
    dbapi_connection.rollback()
sqlite3.ProgrammingError: SQLite objects created in a thread can only be used in that same thread.The object was created in thread id 1676 and this is thread id 8228

During handling of the above exception, another exception occurred:

Traceback (most recent call last):
  File "E:\Work\Programs\Python3.6.0\lib\site-packages\sqlalchemy\pool.py", line 300, in _close_connection
    self._dialect.do_close(connection)
  File "E:\Work\Programs\Python3.6.0\lib\site-packages\sqlalchemy\engine\default.py", line 446, in do_close
    dbapi_connection.close()
sqlite3.ProgrammingError: SQLite objects created in a thread can only be used in that same thread.The object was created in thread id 1676 and this is thread id 8228
2017-04-17 13:14:31,078 [INFO ]  --------------------------------------------------------------------------------
2017-04-17 13:14:31,078 [INFO ]  ****************************| BOT START TIME|2017-04-17 13:14:31.078393|****************************
2017-04-17 13:14:31,078 [INFO ]  --------------------------------------------------------------------------------
2017-04-17 13:14:45,494 [ERROR]  Exception during reset or similar
Traceback (most recent call last):
  File "E:\Work\Programs\Python3.6.0\lib\site-packages\sqlalchemy\pool.py", line 687, in _finalize_fairy
    fairy._reset(pool)
  File "E:\Work\Programs\Python3.6.0\lib\site-packages\sqlalchemy\pool.py", line 829, in _reset
    pool._dialect.do_rollback(self)
  File "E:\Work\Programs\Python3.6.0\lib\site-packages\sqlalchemy\engine\default.py", line 440, in do_rollback
    dbapi_connection.rollback()
sqlite3.ProgrammingError: SQLite objects created in a thread can only be used in that same thread.The object was created in thread id 6232 and this is thread id 10556
2017-04-17 13:14:45,498 [ERROR]  Exception closing connection <sqlite3.Connection object at 0x04E5C620>
Traceback (most recent call last):
  File "E:\Work\Programs\Python3.6.0\lib\site-packages\sqlalchemy\pool.py", line 687, in _finalize_fairy
    fairy._reset(pool)
  File "E:\Work\Programs\Python3.6.0\lib\site-packages\sqlalchemy\pool.py", line 829, in _reset
    pool._dialect.do_rollback(self)
  File "E:\Work\Programs\Python3.6.0\lib\site-packages\sqlalchemy\engine\default.py", line 440, in do_rollback
    dbapi_connection.rollback()
sqlite3.ProgrammingError: SQLite objects created in a thread can only be used in that same thread.The object was created in thread id 6232 and this is thread id 10556

During handling of the above exception, another exception occurred:

Traceback (most recent call last):
  File "E:\Work\Programs\Python3.6.0\lib\site-packages\sqlalchemy\pool.py", line 300, in _close_connection
    self._dialect.do_close(connection)
  File "E:\Work\Programs\Python3.6.0\lib\site-packages\sqlalchemy\engine\default.py", line 446, in do_close
    dbapi_connection.close()
sqlite3.ProgrammingError: SQLite objects created in a thread can only be used in that same thread.The object was created in thread id 6232 and this is thread id 10556
2017-04-17 13:15:13,878 [INFO ]  --------------------------------------------------------------------------------
2017-04-17 13:15:13,878 [INFO ]  ****************************| BOT START TIME|2017-04-17 13:15:13.878077|****************************
2017-04-17 13:15:13,878 [INFO ]  --------------------------------------------------------------------------------
2017-04-17 13:15:27,363 [ERROR]  Exception during reset or similar
Traceback (most recent call last):
  File "E:\Work\Programs\Python3.6.0\lib\site-packages\sqlalchemy\pool.py", line 687, in _finalize_fairy
    fairy._reset(pool)
  File "E:\Work\Programs\Python3.6.0\lib\site-packages\sqlalchemy\pool.py", line 829, in _reset
    pool._dialect.do_rollback(self)
  File "E:\Work\Programs\Python3.6.0\lib\site-packages\sqlalchemy\engine\default.py", line 440, in do_rollback
    dbapi_connection.rollback()
sqlite3.ProgrammingError: SQLite objects created in a thread can only be used in that same thread.The object was created in thread id 10424 and this is thread id 7856
2017-04-17 13:15:27,378 [ERROR]  Exception closing connection <sqlite3.Connection object at 0x040DC620>
Traceback (most recent call last):
  File "E:\Work\Programs\Python3.6.0\lib\site-packages\sqlalchemy\pool.py", line 687, in _finalize_fairy
    fairy._reset(pool)
  File "E:\Work\Programs\Python3.6.0\lib\site-packages\sqlalchemy\pool.py", line 829, in _reset
    pool._dialect.do_rollback(self)
  File "E:\Work\Programs\Python3.6.0\lib\site-packages\sqlalchemy\engine\default.py", line 440, in do_rollback
    dbapi_connection.rollback()
sqlite3.ProgrammingError: SQLite objects created in a thread can only be used in that same thread.The object was created in thread id 10424 and this is thread id 7856

During handling of the above exception, another exception occurred:

Traceback (most recent call last):
  File "E:\Work\Programs\Python3.6.0\lib\site-packages\sqlalchemy\pool.py", line 300, in _close_connection
    self._dialect.do_close(connection)
  File "E:\Work\Programs\Python3.6.0\lib\site-packages\sqlalchemy\engine\default.py", line 446, in do_close
    dbapi_connection.close()
sqlite3.ProgrammingError: SQLite objects created in a thread can only be used in that same thread.The object was created in thread id 10424 and this is thread id 7856
2017-04-17 13:18:59,856 [INFO ]  --------------------------------------------------------------------------------
2017-04-17 13:18:59,856 [INFO ]  ******************| BOT START TIME|2017-04-17 13:18:59.856145|******************
2017-04-17 13:18:59,856 [INFO ]  --------------------------------------------------------------------------------
2017-04-17 13:19:09,302 [ERROR]  --------------------------------------------------------------------------------
2017-04-17 13:19:09,302 [ERROR]  Traceback (most recent call last):
  File "message_handler.py", line 169, in voices_handler
    text_handler(message)
  File "message_handler.py", line 217, in text_handler
    parser = query_parser(message.text)
  File "message_handler.py", line 99, in query_parser
    radius_query = int(radius[0]) if int(radius[0]) <= 50000 else radius_query
ValueError: invalid literal for int() with base 10: ''

2017-04-17 13:19:09,302 [ERROR]  --------------------------------------------------------------------------------
2017-04-17 13:19:09,302 [ERROR]  --------------------------------------------------------------------------------
2017-04-17 13:19:09,302 [ERROR]  invalid literal for int() with base 10: ''
2017-04-17 13:19:09,302 [ERROR]  --------------------------------------------------------------------------------
2017-04-17 13:20:00,746 [INFO ]  --------------------------------------------------------------------------------
2017-04-17 13:20:00,746 [INFO ]  ******************| BOT START TIME|2017-04-17 13:20:00.746786|******************
2017-04-17 13:20:00,746 [INFO ]  --------------------------------------------------------------------------------
2017-04-17 13:21:19,418 [ERROR]  --------------------------------------------------------------------------------
2017-04-17 13:21:19,418 [ERROR]  Traceback (most recent call last):
  File "message_handler.py", line 169, in voices_handler
    text_handler(message)
  File "message_handler.py", line 217, in text_handler
    if parser.get('error', None) is not None:
  File "message_handler.py", line 99, in query_parser
    radius_query = int(radius[0]) if int(radius[0]) <= 50000 else radius_query
ValueError: invalid literal for int() with base 10: ''

2017-04-17 13:21:19,465 [ERROR]  --------------------------------------------------------------------------------
2017-04-17 13:21:19,465 [ERROR]  --------------------------------------------------------------------------------
2017-04-17 13:21:19,465 [ERROR]  invalid literal for int() with base 10: ''
2017-04-17 13:21:19,465 [ERROR]  --------------------------------------------------------------------------------
